Backup failed for Site site1.local. Database or site_config.json may be corrupted
Traceback (most recent call last):
  File "apps/frappe/frappe/commands/site.py", line 764, in backup
    odb = scheduled_backup(
  File "apps/frappe/frappe/utils/backups.py", line 547, in scheduled_backup
    return new_backup(
  File "apps/frappe/frappe/utils/backups.py", line 580, in new_backup
    odb = BackupGenerator(
  File "apps/frappe/frappe/utils/backups.py", line 80, in __init__
    self.setup_backup_tables()
  File "apps/frappe/frappe/utils/backups.py", line 112, in setup_backup_tables
    existing_tables = frappe.db.get_tables()
  File "apps/frappe/frappe/database/mariadb/database.py", line 459, in get_tables
    frappe.qb.from_(information_schema.tables)
  File "apps/frappe/frappe/query_builder/utils.py", line 87, in execute_query
    result = frappe.db.sql(query, params, *args, **kwargs)  # nosemgrep
  File "apps/frappe/frappe/database/database.py", line 194, in sql
    self.connect()
  File "apps/frappe/frappe/database/database.py", line 109, in connect
    self._conn = self.get_connection()
  File "apps/frappe/frappe/database/mariadb/database.py", line 102, in get_connection
    conn = self._get_connection()
  File "apps/frappe/frappe/database/mariadb/database.py", line 108, in _get_connection
    return self.create_connection()
  File "apps/frappe/frappe/database/mariadb/database.py", line 111, in create_connection
    return pymysql.connect(**self.get_connection_settings())
  File "env/lib/python3.10/site-packages/pymysql/connections.py", line 358, in __init__
    self.connect()
  File "env/lib/python3.10/site-packages/pymysql/connections.py", line 664, in connect
    self._request_authentication()
  File "env/lib/python3.10/site-packages/pymysql/connections.py", line 954, in _request_authentication
    auth_packet = self._read_packet()
  File "env/lib/python3.10/site-packages/pymysql/connections.py", line 772, in _read_packet
    packet.raise_for_error()
  File "env/lib/python3.10/site-packages/pymysql/protocol.py", line 221, in raise_for_error
    err.raise_mysql_exception(self._data)
  File "env/lib/python3.10/site-packages/pymysql/err.py", line 143, in raise_mysql_exception
    raise errorclass(errno, errval)
pymysql.err.OperationalError: (1698, "Access denied for user '_03cc9e40ee882297'@'localhost'")

Backup failed for Site techAdemy.local. Database or site_config.json may be corrupted
Traceback (most recent call last):
  File "apps/frappe/frappe/commands/site.py", line 764, in backup
    odb = scheduled_backup(
  File "apps/frappe/frappe/utils/backups.py", line 547, in scheduled_backup
    return new_backup(
  File "apps/frappe/frappe/utils/backups.py", line 580, in new_backup
    odb = BackupGenerator(
  File "apps/frappe/frappe/utils/backups.py", line 80, in __init__
    self.setup_backup_tables()
  File "apps/frappe/frappe/utils/backups.py", line 112, in setup_backup_tables
    existing_tables = frappe.db.get_tables()
  File "apps/frappe/frappe/database/mariadb/database.py", line 459, in get_tables
    frappe.qb.from_(information_schema.tables)
  File "apps/frappe/frappe/query_builder/utils.py", line 87, in execute_query
    result = frappe.db.sql(query, params, *args, **kwargs)  # nosemgrep
  File "apps/frappe/frappe/database/database.py", line 194, in sql
    self.connect()
  File "apps/frappe/frappe/database/database.py", line 109, in connect
    self._conn = self.get_connection()
  File "apps/frappe/frappe/database/mariadb/database.py", line 102, in get_connection
    conn = self._get_connection()
  File "apps/frappe/frappe/database/mariadb/database.py", line 108, in _get_connection
    return self.create_connection()
  File "apps/frappe/frappe/database/mariadb/database.py", line 111, in create_connection
    return pymysql.connect(**self.get_connection_settings())
  File "env/lib/python3.10/site-packages/pymysql/connections.py", line 358, in __init__
    self.connect()
  File "env/lib/python3.10/site-packages/pymysql/connections.py", line 664, in connect
    self._request_authentication()
  File "env/lib/python3.10/site-packages/pymysql/connections.py", line 954, in _request_authentication
    auth_packet = self._read_packet()
  File "env/lib/python3.10/site-packages/pymysql/connections.py", line 772, in _read_packet
    packet.raise_for_error()
  File "env/lib/python3.10/site-packages/pymysql/protocol.py", line 221, in raise_for_error
    err.raise_mysql_exception(self._data)
  File "env/lib/python3.10/site-packages/pymysql/err.py", line 143, in raise_mysql_exception
    raise errorclass(errno, errval)
pymysql.err.OperationalError: (1698, "Access denied for user '_03cc9e40ee882297'@'localhost'")

Backup failed for Site site1.local. Database or site_config.json may be corrupted
Traceback (most recent call last):
  File "apps/frappe/frappe/commands/site.py", line 764, in backup
    odb = scheduled_backup(
  File "apps/frappe/frappe/utils/backups.py", line 547, in scheduled_backup
    return new_backup(
  File "apps/frappe/frappe/utils/backups.py", line 580, in new_backup
    odb = BackupGenerator(
  File "apps/frappe/frappe/utils/backups.py", line 80, in __init__
    self.setup_backup_tables()
  File "apps/frappe/frappe/utils/backups.py", line 112, in setup_backup_tables
    existing_tables = frappe.db.get_tables()
  File "apps/frappe/frappe/database/mariadb/database.py", line 459, in get_tables
    frappe.qb.from_(information_schema.tables)
  File "apps/frappe/frappe/query_builder/utils.py", line 87, in execute_query
    result = frappe.db.sql(query, params, *args, **kwargs)  # nosemgrep
  File "apps/frappe/frappe/database/database.py", line 194, in sql
    self.connect()
  File "apps/frappe/frappe/database/database.py", line 109, in connect
    self._conn = self.get_connection()
  File "apps/frappe/frappe/database/mariadb/database.py", line 102, in get_connection
    conn = self._get_connection()
  File "apps/frappe/frappe/database/mariadb/database.py", line 108, in _get_connection
    return self.create_connection()
  File "apps/frappe/frappe/database/mariadb/database.py", line 111, in create_connection
    return pymysql.connect(**self.get_connection_settings())
  File "env/lib/python3.10/site-packages/pymysql/connections.py", line 358, in __init__
    self.connect()
  File "env/lib/python3.10/site-packages/pymysql/connections.py", line 664, in connect
    self._request_authentication()
  File "env/lib/python3.10/site-packages/pymysql/connections.py", line 954, in _request_authentication
    auth_packet = self._read_packet()
  File "env/lib/python3.10/site-packages/pymysql/connections.py", line 772, in _read_packet
    packet.raise_for_error()
  File "env/lib/python3.10/site-packages/pymysql/protocol.py", line 221, in raise_for_error
    err.raise_mysql_exception(self._data)
  File "env/lib/python3.10/site-packages/pymysql/err.py", line 143, in raise_mysql_exception
    raise errorclass(errno, errval)
pymysql.err.OperationalError: (1698, "Access denied for user '_03cc9e40ee882297'@'localhost'")

Backup failed for Site techAdemy.local. Database or site_config.json may be corrupted
Traceback (most recent call last):
  File "apps/frappe/frappe/commands/site.py", line 764, in backup
    odb = scheduled_backup(
  File "apps/frappe/frappe/utils/backups.py", line 547, in scheduled_backup
    return new_backup(
  File "apps/frappe/frappe/utils/backups.py", line 580, in new_backup
    odb = BackupGenerator(
  File "apps/frappe/frappe/utils/backups.py", line 80, in __init__
    self.setup_backup_tables()
  File "apps/frappe/frappe/utils/backups.py", line 112, in setup_backup_tables
    existing_tables = frappe.db.get_tables()
  File "apps/frappe/frappe/database/mariadb/database.py", line 459, in get_tables
    frappe.qb.from_(information_schema.tables)
  File "apps/frappe/frappe/query_builder/utils.py", line 87, in execute_query
    result = frappe.db.sql(query, params, *args, **kwargs)  # nosemgrep
  File "apps/frappe/frappe/database/database.py", line 194, in sql
    self.connect()
  File "apps/frappe/frappe/database/database.py", line 109, in connect
    self._conn = self.get_connection()
  File "apps/frappe/frappe/database/mariadb/database.py", line 102, in get_connection
    conn = self._get_connection()
  File "apps/frappe/frappe/database/mariadb/database.py", line 108, in _get_connection
    return self.create_connection()
  File "apps/frappe/frappe/database/mariadb/database.py", line 111, in create_connection
    return pymysql.connect(**self.get_connection_settings())
  File "env/lib/python3.10/site-packages/pymysql/connections.py", line 358, in __init__
    self.connect()
  File "env/lib/python3.10/site-packages/pymysql/connections.py", line 664, in connect
    self._request_authentication()
  File "env/lib/python3.10/site-packages/pymysql/connections.py", line 954, in _request_authentication
    auth_packet = self._read_packet()
  File "env/lib/python3.10/site-packages/pymysql/connections.py", line 772, in _read_packet
    packet.raise_for_error()
  File "env/lib/python3.10/site-packages/pymysql/protocol.py", line 221, in raise_for_error
    err.raise_mysql_exception(self._data)
  File "env/lib/python3.10/site-packages/pymysql/err.py", line 143, in raise_mysql_exception
    raise errorclass(errno, errval)
pymysql.err.OperationalError: (1698, "Access denied for user '_03cc9e40ee882297'@'localhost'")

